Workbook

Sheet P_index 2020
A1: Data extracted on 30/01/2026 17:26:20 from [ESTAT]
A2: Dataset:
A3: Last updated:
A5: Time frequency
A6: Unit of measure
A7: Statistical classification of economic activities in the European Community (NACE Rev. 2)
A8: National accounts indicator (ESA 2010)
A10: TIME | B10: 1995 | C10: 1996 | D10: 1997 | E10: 1998 | F10: 1999 | G10: 2000 | H10: 2001 | I10: 2002 | J10: 2003 | K10: 2004 | L10: 2005 | M10: 2006 | N10: 2007 | O10: 2008 | P10: 2009 | Q10: 2010 | R10: 2011 | S10: 2012 | T10: 2013 | U10: 2014 | V10: 2015 | W10: 2016 | X10: 2017 | Y10: 2018 | Z10: 2019 | AA10: 2020 | AB10: 2021 | AC10: 2022 | AD10: 2023 | AE10: 2024
A11: Belgium | B11: 66.896 | C11: 67.739 | D11: 71.433 | E11: 74.33 | F11: 77.533 | G11: 79.117 | H11: 81.436 | I11: 80.462 | J11: 80.807 | K11: 83.597 | L11: 85.312 | M11: 88.525 | N11: 91.84 | O11: 92.899 | P11: 87.684 | Q11: 92.101 | R11: 95.504 | S11: 94.4 | T11: 93.934 | U11: 95.412 | V11: 96.969 | W11: 98.996 | X11: 101.306 | Y11: 103.529 | Z11: 106.031 | AA11: 100 | AB11: 110.251 | AC11: 112.675 | AD11: 110.591 | AE11: 110.983
A12: Bulgaria | B12: : | C12: : | D12: : | E12: : | F12: : | G12: : | H12: : | I12: : | J12: : | K12: : | L12: : | M12: : | N12: : | O12: : | P12: : | Q12: : | R12: : | S12: : | T12: : | U12: : | V12: : | W12: : | X12: : | Y12: : | Z12: : | AA12: : | AB12: : | AC12: : | AD12: : | AE12: :
A13: Czechia | B13: 48.71 | C13: 50.954 | D13: 52.86 | E13: 53.778 | F13: 54.045 | G13: 56.69 | H13: 60.204 | I13: 61.871 | J13: 66.039 | K13: 69.89 | L13: 73.181 | M13: 80.169 | N13: 86.315 | O13: 87.898 | P13: 80.79 | Q13: 84.567 | R13: 86.852 | S13: 84.811 | T13: 84.698 | U13: 87.817 | V13: 92.25 | W13: 94.651 | X13: 100.336 | Y13: 104.411 | Z13: 106.14 | AA13: 100 | AB13: 106.784 | AC13: 111.34 | AD13: 111.651 | AE13: 112.931
A14: Denmark | B14: 62.827 | C14: 64.66 | D14: 66.671 | E14: 68.595 | F14: 71.43 | G14: 74.942 | H14: 76.778 | I14: 77.667 | J14: 77.837 | K14: 79.626 | L14: 83.867 | M14: 88.36 | N14: 90.966 | O14: 91.745 | P14: 85.823 | Q14: 85.879 | R14: 88.057 | S14: 88.745 | T14: 88.874 | U14: 90.736 | V14: 92.977 | W14: 96.329 | X14: 98.865 | Y14: 100.686 | Z14: 102.23 | AA14: 100 | AB14: 106.342 | AC14: 109.268 | AD14: 109.443 | AE14: 112.259
A15: Germany | B15: 65.46 | C15: 66.45 | D15: 67.96 | E15: 70.38 | F15: 73.02 | G15: 75.98 | H15: 77.55 | I15: 76.85 | J15: 77.58 | K15: 79.14 | L15: 80.81 | M15: 84.45 | N15: 88.15 | O15: 89.75 | P15: 83.8 | Q15: 88.5 | R15: 92.35 | S15: 91.85 | T15: 91.74 | U15: 93.74 | V15: 95.67 | W15: 97.82 | X15: 100.57 | Y15: 102.41 | Z15: 103.55 | AA15: 100 | AB15: 103.59 | AC15: 107.01 | AD15: 107.22 | AE15: 106.29
A16: Estonia | B16: 30.712 | C16: 32.226 | D16: 36.899 | E16: 39.69 | F16: 39.202 | G16: 43.604 | H16: 47.524 | I16: 51.308 | J16: 55.057 | K16: 60.198 | L16: 66.705 | M16: 73.276 | N16: 78.913 | O16: 76.069 | P16: 62.099 | Q16: 66.781 | R16: 74.123 | S16: 76.984 | T16: 79.337 | U16: 81.53 | V16: 83.048 | W16: 86.189 | X16: 92.068 | Y16: 96.376 | Z16: 100.902 | AA16: 100 | AB16: 109.52 | AC16: 112.623 | AD16: 108.932 | AE16: 107.853
A17: Ireland | B17: : | C17: : | D17: : | E17: : | F17: : | G17: : | H17: : | I17: : | J17: : | K17: : | L17: : | M17: : | N17: : | O17: : | P17: : | Q17: : | R17: : | S17: : | T17: : | U17: : | V17: : | W17: : | X17: : | Y17: : | Z17: : | AA17: : | AB17: : | AC17: : | AD17: : | AE17: :
A18: Greece | B18: 95.569 | C18: 96.935 | D18: 98.92 | E18: 102.858 | F18: 105.22 | G18: 109.855 | H18: 114.315 | I18: 119.446 | J18: 123.484 | K18: 129.877 | L18: 128.971 | M18: 137.141 | N18: 141.209 | O18: 137.316 | P18: 132.377 | Q18: 123.201 | R18: 110.552 | S18: 103.485 | T18: 103.45 | U18: 103.803 | V18: 106.338 | W18: 105.118 | X18: 107.609 | Y18: 110.022 | Z18: 112.694 | AA18: 100 | AB18: 109.659 | AC18: 120.667 | AD18: 124.656 | AE18: 126.678
A19: Spain | B19: : | C19: : | D19: : | E19: : | F19: : | G19: : | H19: : | I19: : | J19: : | K19: : | L19: : | M19: : | N19: : | O19: : | P19: : | Q19: : | R19: : | S19: : | T19: : | U19: : | V19: : | W19: : | X19: : | Y19: : | Z19: : | AA19: : | AB19: : | AC19: : | AD19: : | AE19: :
A20: France | B20: 68.492 | C20: 69.507 | D20: 71.723 | E20: 74.853 | F20: 78.342 | G20: 82.816 | H20: 85.011 | I20: 85.719 | J20: 86.045 | K20: 88.666 | L20: 90.768 | M20: 93.723 | N20: 96.578 | O20: 96.811 | P20: 92.114 | Q20: 94.591 | R20: 96.653 | S20: 96.473 | T20: 96.897 | U20: 98.112 | V20: 99.544 | W20: 100.762 | X20: 104.007 | Y20: 106.111 | Z20: 108.383 | AA20: 100 | AB20: 107.67 | AC20: 112.734 | AD20: 114.947 | AE20: 116.303
A21: Croatia | B21: : | C21: : | D21: : | E21: : | F21: : | G21: : | H21: : | I21: : | J21: : | K21: : | L21: : | M21: : | N21: : | O21: : | P21: : | Q21: : | R21: : | S21: : | T21: : | U21: : | V21: : | W21: : | X21: : | Y21: : | Z21: : | AA21: : | AB21: : | AC21: : | AD21: : | AE21: :
A22: Italy | B22: : | C22: : | D22: : | E22: : | F22: : | G22: : | H22: : | I22: : | J22: : | K22: : | L22: : | M22: : | N22: : | O22: : | P22: : | Q22: : | R22: : | S22: : | T22: : | U22: : | V22: : | W22: : | X22: : | Y22: : | Z22: : | AA22: : | AB22: : | AC22: : | AD22: : | AE22: :
A23: Cyprus | B23: : | C23: : | D23: : | E23: : | F23: : | G23: : | H23: : | I23: : | J23: : | K23: : | L23: : | M23: : | N23: : | O23: : | P23: : | Q23: : | R23: : | S23: : | T23: : | U23: : | V23: : | W23: : | X23: : | Y23: : | Z23: : | AA23: : | AB23: : | AC23: : | AD23: : | AE23: :
A24: Latvia | B24: 48.024 | C24: 49.755 | D24: 54.923 | E24: 57.183 | F24: 58.263 | G24: 62.68 | H24: 63.314 | I24: 67.909 | J24: 72.516 | K24: 78.746 | L24: 87.843 | M24: 98.979 | N24: 107.742 | O24: 105.756 | P24: 87.945 | Q24: 87.023 | R24: 92.08 | S24: 96.884 | T24: 98.268 | U24: 97.036 | V24: 97.322 | W24: 96.348 | X24: 100.914 | Y24: 104.461 | Z24: 105.369 | AA24: 100 | AB24: 108.028 | AC24: 112.072 | AD24: 107.184 | AE24: 106.214
A25: Lithuania | B25: : | C25: : | D25: : | E25: : | F25: : | G25: : | H25: : | I25: : | J25: : | K25: : | L25: : | M25: : | N25: : | O25: : | P25: : | Q25: : | R25: : | S25: : | T25: : | U25: : | V25: : | W25: : | X25: : | Y25: : | Z25: : | AA25: : | AB25: : | AC25: : | AD25: : | AE25: :
A26: Luxembourg | B26: 26.251 | C26: 27.137 | D26: 29.479 | E26: 33.182 | F26: 37.578 | G26: 42.939 | H26: 45.799 | I26: 46.717 | J26: 48.751 | K26: 51.924 | L26: 54.632 | M26: 61.124 | N26: 64.863 | O26: 65.185 | P26: 61.685 | Q26: 67.955 | R26: 69.644 | S26: 71.069 | T26: 75.381 | U26: 81.22 | V26: 87.092 | W26: 89.521 | X26: 90.791 | Y26: 93.952 | Z26: 98.003 | AA26: 100 | AB26: 110.216 | AC26: 108.525 | AD26: 108.68 | AE26: 100.098
A27: Hungary | B27: 40.903 | C27: 42 | D27: 44.494 | E27: 47.675 | F27: 50.088 | G27: 54.065 | H27: 58.489 | I27: 62.958 | J27: 66.254 | K27: 70.458 | L27: 74.493 | M27: 77.991 | N27: 78.117 | O27: 80.374 | P27: 73.12 | Q27: 74.822 | R27: 76.424 | S27: 73.746 | T27: 76.741 | U27: 81.62 | V27: 85.42 | W27: 87.595 | X27: 91.757 | Y27: 97.62 | Z27: 103.418 | AA27: 100 | AB27: 108.078 | AC27: 113.164 | AD27: 109.492 | AE27: 108.482
A28: Malta | B28: : | C28: : | D28: : | E28: : | F28: : | G28: : | H28: : | I28: : | J28: : | K28: : | L28: : | M28: : | N28: : | O28: : | P28: : | Q28: : | R28: : | S28: : | T28: : | U28: : | V28: : | W28: : | X28: : | Y28: : | Z28: : | AA28: : | AB28: : | AC28: : | AD28: : | AE28: :
A29: Netherlands | B29: 57.093 | C29: 59.707 | D29: 63.021 | E29: 66.584 | F29: 70.13 | G29: 73.498 | H29: 75.151 | I29: 75.026 | J29: 74.807 | K29: 76.332 | L29: 78.205 | M29: 80.961 | N29: 84.223 | O29: 85.96 | P29: 82.897 | Q29: 83.553 | R29: 86.139 | S29: 85.9 | T29: 86.244 | U29: 88.299 | V29: 91.698 | W29: 94.41 | X29: 97.726 | Y29: 101.75 | Z29: 103.815 | AA29: 100 | AB29: 105.221 | AC29: 110.28 | AD29: 110.13 | AE29: 110.894
A30: Austria | B30: 58.881 | C30: 60.459 | D30: 62.457 | E30: 64.927 | F30: 67.466 | G30: 70.692 | H30: 72.783 | I30: 74.37 | J30: 75.969 | K30: 78.909 | L30: 82.177 | M30: 86.362 | N30: 89.735 | O30: 92.165 | P30: 88.126 | Q30: 90.19 | R30: 93.283 | S30: 94.476 | T30: 94.793 | U30: 94.93 | V30: 96.352 | W30: 97.64 | X30: 100.81 | Y30: 104.272 | Z30: 106.362 | AA30: 100 | AB30: 106.458 | AC30: 112.619 | AD30: 110.481 | AE30: 108.46
A31: Poland | B31: : | C31: : | D31: : | E31: : | F31: : | G31: : | H31: : | I31: : | J31: : | K31: : | L31: : | M31: : | N31: : | O31: : | P31: : | Q31: : | R31: : | S31: : | T31: : | U31: : | V31: : | W31: : | X31: : | Y31: : | Z31: : | AA31: : | AB31: : | AC31: : | AD31: : | AE31: :
A32: Portugal | B32: : | C32: : | D32: : | E32: : | F32: : | G32: : | H32: : | I32: : | J32: : | K32: : | L32: : | M32: : | N32: : | O32: : | P32: : | Q32: : | R32: : | S32: : | T32: : | U32: : | V32: : | W32: : | X32: : | Y32: : | Z32: : | AA32: : | AB32: : | AC32: : | AD32: : | AE32: :
A33: Romania | B33: 41.128 | C33: 43.526 | D33: 41.369 | E33: 39.533 | F33: 40.89 | G33: 42.472 | H33: 45.898 | I33: 48.363 | J33: 51.201 | K33: 56.425 | L33: 58.955 | M33: 64.519 | N33: 68.5 | O33: 75.424 | P33: 71.723 | Q33: 72.896 | R33: 77.047 | S33: 77.939 | T33: 79.276 | U33: 82.761 | V33: 85.172 | W33: 87.903 | X33: 94.221 | Y33: 99.435 | Z33: 104.204 | AA33: 100 | AB33: 105.933 | AC33: 112.723 | AD33: 112.652 | AE33: 112.557
A34: Slovenia | B34: : | C34: : | D34: : | E34: : | F34: : | G34: : | H34: : | I34: : | J34: : | K34: : | L34: : | M34: : | N34: : | O34: : | P34: : | Q34: : | R34: : | S34: : | T34: : | U34: : | V34: : | W34: : | X34: : | Y34: : | Z34: : | AA34: : | AB34: : | AC34: : | AD34: : | AE34: :
A35: Slovakia | B35: : | C35: : | D35: : | E35: : | F35: : | G35: : | H35: : | I35: : | J35: : | K35: : | L35: : | M35: : | N35: : | O35: : | P35: : | Q35: : | R35: : | S35: : | T35: : | U35: : | V35: : | W35: : | X35: : | Y35: : | Z35: : | AA35: : | AB35: : | AC35: : | AD35: : | AE35: :
A36: Finland | B36: 59.12 | C36: 61.448 | D36: 65.685 | E36: 69.885 | F36: 73.679 | G36: 79.016 | H36: 79.963 | I36: 81.394 | J36: 82.816 | K36: 86.436 | L36: 89.499 | M36: 93.97 | N36: 98.685 | O36: 100.157 | P36: 90.528 | Q36: 92.554 | R36: 95.367 | S36: 94.5 | T36: 93.155 | U36: 92.988 | V36: 92.476 | W36: 95.292 | X36: 98.6 | Y36: 100.542 | Z36: 102.877 | AA36: 100 | AB36: 103.166 | AC36: 105.268 | AD36: 103.351 | AE36: 102.767
A37: Sweden | B37: 58.334 | C37: 59.227 | D37: 61.503 | E37: 64.405 | F37: 67.061 | G37: 70.841 | H37: 71.697 | I37: 72.127 | J37: 72.867 | K37: 75.743 | L37: 78.24 | M37: 82.059 | N37: 85.443 | O37: 85.249 | P37: 79.709 | Q37: 83.53 | R37: 86.706 | S37: 86.234 | T37: 86.49 | U37: 88.436 | V37: 92.183 | W37: 94.923 | X37: 97.567 | Y37: 100.106 | Z37: 102.53 | AA37: 100 | AB37: 104.594 | AC37: 107.895 | AD37: 109.245 | AE37: :
A38: Iceland | B38: 48.811 | C38: 51.957 | D38: 54.353 | E38: 58.412 | F38: 61.233 | G38: 64.499 | H38: 66.929 | I38: 66.511 | J38: 68.387 | K38: 73.168 | L38: 76.546 | M38: 79.018 | N38: 85.105 | O38: 86.607 | P38: 80.58 | Q38: 78.53 | R38: 80.501 | S38: 82.256 | T38: 86.421 | U38: 88.246 | V38: 92.618 | W38: 98.721 | X38: 103.467 | Y38: 108.725 | Z38: 109.907 | AA38: 100 | AB38: 105.84 | AC38: 117.175 | AD38: 122.39 | AE38: :
A39: Liechtenstein | B39: : | C39: : | D39: : | E39: : | F39: : | G39: : | H39: : | I39: : | J39: : | K39: : | L39: : | M39: : | N39: : | O39: : | P39: : | Q39: : | R39: : | S39: : | T39: : | U39: : | V39: : | W39: : | X39: : | Y39: : | Z39: : | AA39: : | AB39: : | AC39: : | AD39: : | AE39: :
A40: Norway | B40: : | C40: : | D40: : | E40: : | F40: : | G40: : | H40: : | I40: : | J40: : | K40: : | L40: : | M40: : | N40: : | O40: : | P40: : | Q40: : | R40: : | S40: : | T40: : | U40: : | V40: : | W40: : | X40: : | Y40: : | Z40: : | AA40: : | AB40: : | AC40: : | AD40: : | AE40: :
A41: Switzerland | B41: : | C41: 60.905 | D41: 62.544 | E41: 64.759 | F41: 66.077 | G41: 68.65 | H41: 69.444 | I41: 70.102 | J41: 69.751 | K41: 72.436 | L41: 74.795 | M41: 78.518 | N41: 82.369 | O41: 84.953 | P41: 83.435 | Q41: 85.13 | R41: 86.25 | S41: 87.966 | T41: 89.249 | U41: 91.075 | V41: 92.427 | W41: 94.35 | X41: 97.076 | Y41: 100.827 | Z41: 103.067 | AA41: 100 | AB41: 111.424 | AC41: 117.587 | AD41: 116.842 | AE41: :
A42: United Kingdom | B42: : | C42: : | D42: : | E42: : | F42: : | G42: : | H42: : | I42: : | J42: : | K42: : | L42: : | M42: : | N42: : | O42: : | P42: : | Q42: : | R42: : | S42: : | T42: : | U42: : | V42: : | W42: : | X42: : | Y42: : | Z42: : | AA42: : | AB42: : | AC42: : | AD42: : | AE42: :
...

Sheet Q_chain_2020
A5: Time frequency
A6: Unit of measure
A7: Statistical classification of economic activities in the European Community (NACE Rev. 2)
A8: National accounts indicator (ESA 2010)
A10: TIME | B10: 1995 | C10: 1996 | D10: 1997 | E10: 1998 | F10: 1999 | G10: 2000 | H10: 2001 | I10: 2002 | J10: 2003 | K10: 2004 | L10: 2005 | M10: 2006 | N10: 2007 | O10: 2008 | P10: 2009 | Q10: 2010 | R10: 2011 | S10: 2012 | T10: 2013 | U10: 2014 | V10: 2015 | W10: 2016 | X10: 2017 | Y10: 2018 | Z10: 2019 | AA10: 2020 | AB10: 2021 | AC10: 2022 | AD10: 2023 | AE10: 2024
A11: Belgium | B11: 629485.4 | C11: 637415 | D11: 672177.4 | E11: 699439 | F11: 729576.4 | G11: 744480.6 | H11: 766311 | I11: 757138.5 | J11: 760385.3 | K11: 786638.9 | L11: 802780.8 | M11: 833009.3 | N11: 864203.1 | O11: 874171 | P11: 825097.3 | Q11: 866659.5 | R11: 898688.5 | S11: 888297.3 | T11: 883909.1 | U11: 897819.4 | V11: 912467.4 | W11: 931548 | X11: 953280.7 | Y11: 974202 | Z11: 997739.6 | AA11: 940992.2 | AB11: 1037456.8 | AC11: 1060261.7 | AD11: 1040652.3 | AE11: 1044337.6
A12: Bulgaria | B12: : | C12: : | D12: : | E12: : | F12: : | G12: : | H12: : | I12: : | J12: : | K12: : | L12: : | M12: : | N12: : | O12: : | P12: : | Q12: : | R12: : | S12: : | T12: : | U12: : | V12: : | W12: : | X12: : | Y12: : | Z12: : | AA12: : | AB12: : | AC12: : | AD12: : | AE12: :
A13: Czechia | B13: 230899.1 | C13: 241534.1 | D13: 250568.5 | E13: 254922 | F13: 256184.5 | G13: 268725.7 | H13: 285383.6 | I13: 293283.7 | J13: 313039.9 | K13: 331297.3 | L13: 346896.8 | M13: 380018.4 | N13: 409152.3 | O13: 416658 | P13: 382966.2 | Q13: 400868.8 | R13: 411701.3 | S13: 402025.6 | T13: 401489.2 | U13: 416275.2 | V13: 437286.3 | W13: 448668.6 | X13: 475616.2 | Y13: 494933.1 | Z13: 503131.3 | AA13: 474024.3 | AB13: 506181.2 | AC13: 527780.6 | AD13: 529251.6 | AE13: 535319.5
A14: Denmark | B14: 341810.4 | C14: 351781.7 | D14: 362723.5 | E14: 373187.9 | F14: 388614.8 | G14: 407720.8 | H14: 417707.4 | I14: 422546.8 | J14: 423469 | K14: 433205 | L14: 456278 | M14: 480721.6 | N14: 494895.4 | O14: 499133.5 | P14: 466915 | Q14: 467221.6 | R14: 479071.5 | S14: 482812 | T14: 483516 | U14: 493646.1 | V14: 505838.1 | W14: 524075.9 | X14: 537872.7 | Y14: 547777.5 | Z14: 556177.7 | AA14: 544046.5 | AB14: 578547.4 | AC14: 594467.9 | AD14: 595420.4 | AE14: 610741
A15: Germany | B15: 4143508 | C15: 4206173.4 | D15: 4301753.8 | E15: 4454935.8 | F15: 4622043.3 | G15: 4809406.4 | H15: 4908784.7 | I15: 4864475.9 | J15: 4910683.7 | K15: 5009429 | L15: 5115137.2 | M15: 5345543.1 | N15: 5579746.9 | O15: 5681024.2 | P15: 5304399.2 | Q15: 5601901.3 | R15: 5845599.9 | S15: 5813950.7 | T15: 5806987.9 | U15: 5933584.5 | V15: 6055750.3 | W15: 6191841.7 | X15: 6365912 | Y15: 6482381 | Z15: 6554541 | AA15: 6329832 | AB15: 6557073 | AC15: 6773553.2 | AD15: 6786845.9 | AE15: 6727978.4
A16: Estonia | B16: 16578.5 | C16: 17395.8 | D16: 19918.2 | E16: 21424.8 | F16: 21161.7 | G16: 23537.5 | H16: 25654 | I16: 27696.3 | J16: 29720.1 | K16: 32495.1 | L16: 36008 | M16: 39555 | N16: 42597.6 | O16: 41062.4 | P16: 33521.7 | Q16: 36048.6 | R16: 40012.1 | S16: 41556.3 | T16: 42826.7 | U16: 44010.5 | V16: 44829.8 | W16: 46525.2 | X16: 49699 | Y16: 52024.2 | Z16: 54467.5 | AA16: 53980.6 | AB16: 59119.6 | AC16: 60794.4 | AD16: 58802.4 | AE16: 58219.6
A17: Ireland | B17: : | C17: : | D17: : | E17: : | F17: : | G17: : | H17: : | I17: : | J17: : | K17: : | L17: : | M17: : | N17: : | O17: : | P17: : | Q17: : | R17: : | S17: : | T17: : | U17: : | V17: : | W17: : | X17: : | Y17: : | Z17: : | AA17: : | AB17: : | AC17: : | AD17: : | AE17: :
A18: Greece | B18: 256950.1 | C18: 260622 | D18: 265961.1 | E18: 276547.3 | F18: 282898.4 | G18: 295361.8 | H18: 307350.8 | I18: 321147.5 | J18: 332003.2 | K18: 349191.7 | L18: 346757.8 | M18: 368721.5 | N18: 379660.5 | O18: 369193.9 | P18: 355913.9 | Q18: 331244.1 | R18: 297233.5 | S18: 278233.2 | T18: 278141.1 | U18: 279088.1 | V18: 285905.3 | W18: 282625 | X18: 289320.5 | Y18: 295810.3 | Z18: 302992.4 | AA18: 268864 | AB18: 294834.5 | AC18: 324429.2 | AD18: 335154.8 | AE18: 340591.6
A19: Spain | B19: : | C19: : | D19: : | E19: : | F19: : | G19: : | H19: : | I19: : | J19: : | K19: : | L19: : | M19: : | N19: : | O19: : | P19: : | Q19: : | R19: : | S19: : | T19: : | U19: : | V19: : | W19: : | X19: : | Y19: : | Z19: : | AA19: : | AB19: : | AC19: : | AD19: : | AE19: :
A20: France | B20: 2791047.6 | C20: 2832406.4 | D20: 2922718.2 | E20: 3050274.7 | F20: 3192426.5 | G20: 3374768.3 | H20: 3464219.4 | I20: 3493064 | J20: 3506361.2 | K20: 3613158.3 | L20: 3698821.4 | M20: 3819211 | N20: 3935573.5 | O20: 3945078 | P20: 3753671 | Q20: 3854596.2 | R20: 3938626.1 | S20: 3931265.5 | T20: 3948554.1 | U20: 3998086.3 | V20: 4056421.8 | W20: 4106052.2 | X20: 4238291.6 | Y20: 4324039.2 | Z20: 4416630.2 | AA20: 4075011.5 | AB20: 4387581 | AC20: 4593940.1 | AD20: 4684088.1 | AE20: 4739374
A21: Croatia | B21: : | C21: : | D21: : | E21: : | F21: : | G21: : | H21: : | I21: : | J21: : | K21: : | L21: : | M21: : | N21: : | O21: : | P21: : | Q21: : | R21: : | S21: : | T21: : | U21: : | V21: : | W21: : | X21: : | Y21: : | Z21: : | AA21: : | AB21: : | AC21: : | AD21: : | AE21: :
A22: Italy | B22: : | C22: : | D22: : | E22: : | F22: : | G22: : | H22: : | I22: : | J22: : | K22: : | L22: : | M22: : | N22: : | O22: : | P22: : | Q22: : | R22: : | S22: : | T22: : | U22: : | V22: : | W22: : | X22: : | Y22: : | Z22: : | AA22: : | AB22: : | AC22: : | AD22: : | AE22: :
A23: Cyprus | B23: : | C23: : | D23: : | E23: : | F23: : | G23: : | H23: : | I23: : | J23: : | K23: : | L23: : | M23: : | N23: : | O23: : | P23: : | Q23: : | R23: : | S23: : | T23: : | U23: : | V23: : | W23: : | X23: : | Y23: : | Z23: : | AA23: : | AB23: : | AC23: : | AD23: : | AE23: :
A24: Latvia | B24: 25114.2 | C24: 26019.6 | D24: 28722.3 | E24: 29903.9 | F24: 30468.9 | G24: 32779 | H24: 33110.5 | I24: 35513.3 | J24: 37922.6 | K24: 41180.4 | L24: 45938 | M24: 51761.5 | N24: 56344.3 | O24: 55305.6 | P24: 45991.5 | Q24: 45509 | R24: 48153.9 | S24: 50666 | T24: 51389.8 | U24: 50745.4 | V24: 50895.2 | W24: 50385.6 | X24: 52773.2 | Y24: 54628.5 | Z24: 55103.1 | AA24: 52295.5 | AB24: 56493.5 | AC24: 58608.4 | AD24: 56052.6 | AE24: 55545.1
A25: Lithuania | B25: : | C25: : | D25: : | E25: : | F25: : | G25: : | H25: : | I25: : | J25: : | K25: : | L25: : | M25: : | N25: : | O25: : | P25: : | Q25: : | R25: : | S25: : | T25: : | U25: : | V25: : | W25: : | X25: : | Y25: : | Z25: : | AA25: : | AB25: : | AC25: : | AD25: : | AE25: :
A26: Luxembourg | B26: 59333.7 | C26: 61336.1 | D26: 66629.9 | E26: 74999.1 | F26: 84934.1 | G26: 97051.5 | H26: 103516.8 | I26: 105591.1 | J26: 110188.6 | K26: 117359.6 | L26: 123480.3 | M26: 138154.4 | N26: 146604.6 | O26: 147332.6 | P26: 139422.5 | Q26: 153593.1 | R26: 157411.9 | S26: 160632.3 | T26: 170378.6 | U26: 183575.9 | V26: 196847.1 | W26: 202337 | X26: 205208.7 | Y26: 212352.4 | Z26: 221508.6 | AA26: 226022.2 | AB26: 249112.7 | AC26: 245289.7 | AD26: 245640.7 | AE26: 226243.2
A27: Hungary | B27: 109664.9 | C27: 112606.3 | D27: 119294 | E27: 127820.8 | F27: 134291.6 | G27: 144954.3 | H27: 156814.3 | I27: 168796 | J27: 177634.4 | K27: 188905.1 | L27: 199722.6 | M27: 209102.5 | N27: 209438.9 | O27: 215490.2 | P27: 196041.9 | Q27: 200606.2 | R27: 204899.3 | S27: 197720.4 | T27: 205748.8 | U27: 218830.3 | V27: 229019 | W27: 234850.3 | X27: 246008.7 | Y27: 261727.6 | Z27: 277272.9 | AA27: 268109.6 | AB27: 289767.3 | AC27: 303404.1 | AD27: 293559.2 | AE27: 290851.3
A28: Malta | B28: : | C28: : | D28: : | E28: : | F28: : | G28: : | H28: : | I28: : | J28: : | K28: : | L28: : | M28: : | N28: : | O28: : | P28: : | Q28: : | R28: : | S28: : | T28: : | U28: : | V28: : | W28: : | X28: : | Y28: : | Z28: : | AA28: : | AB28: : | AC28: : | AD28: : | AE28: :
A29: Netherlands | B29: 898597.3 | C29: 939735.6 | D29: 991891.3 | E29: 1047973.6 | F29: 1103778.6 | G29: 1156788.8 | H29: 1182809.2 | I29: 1180839.5 | J29: 1177392.8 | K29: 1201403.5 | L29: 1230879.8 | M29: 1274254.9 | N29: 1325601.9 | O29: 1352941.3 | P29: 1304732.3 | Q29: 1315055.9 | R29: 1355757.1 | S29: 1351990.3 | T29: 1357401.4 | U29: 1389747.7 | V29: 1443251.8 | W29: 1485925.8 | X29: 1538122.7 | Y29: 1601456.1 | Z29: 1633951.3 | AA29: 1573914 | AB29: 1656093 | AC29: 1735711.1 | AD29: 1733349.3 | AE29: 1745378.8
A30: Austria | B30: 411332.2 | C30: 422353.3 | D30: 436310.4 | E30: 453564.8 | F30: 471306.3 | G30: 493840.5 | H30: 508445.6 | I30: 519532.6 | J30: 530701.3 | K30: 551238.8 | L30: 574072.7 | M30: 603306.7 | N30: 626866.6 | O30: 643842.1 | P30: 615625.9 | Q30: 630046.3 | R30: 651654.1 | S30: 659991.5 | T30: 662205.2 | U30: 663158.7 | V30: 673094 | W30: 682090.3 | X30: 704234.7 | Y30: 728418.3 | Z30: 743021.4 | AA30: 698578.3 | AB30: 743694.8 | AC30: 786735.1 | AD30: 771793.1 | AE30: 757675.6
A31: Poland | B31: : | C31: : | D31: : | E31: : | F31: : | G31: : | H31: : | I31: : | J31: : | K31: : | L31: : | M31: : | N31: : | O31: : | P31: : | Q31: : | R31: : | S31: : | T31: : | U31: : | V31: : | W31: : | X31: : | Y31: : | Z31: : | AA31: : | AB31: : | AC31: : | AD31: : | AE31: :
A32: Portugal | B32: : | C32: : | D32: : | E32: : | F32: : | G32: : | H32: : | I32: : | J32: : | K32: : | L32: : | M32: : | N32: : | O32: : | P32: : | Q32: : | R32: : | S32: : | T32: : | U32: : | V32: : | W32: : | X32: : | Y32: : | Z32: : | AA32: : | AB32: : | AC32: : | AD32: : | AE32: :
A33: Romania | B33: 166014.5 | C33: 175694.1 | D33: 166987.2 | E33: 159573.8 | F33: 165051.7 | G33: 171437 | H33: 185266 | I33: 195216.8 | J33: 206672.3 | K33: 227759 | L33: 237973.2 | M33: 260430 | N33: 276502.7 | O33: 304451.3 | P33: 289510.2 | Q33: 294244.3 | R33: 311002.9 | S33: 314599.8 | T33: 319999.6 | U33: 334065.2 | V33: 343796.9 | W33: 354819.5 | X33: 380325.5 | Y33: 401370.2 | Z33: 420619.5 | AA33: 403651 | AB33: 427598.2 | AC33: 455005.7 | AD33: 454719 | AE33: 454338.5
A34: Slovenia | B34: : | C34: : | D34: : | E34: : | F34: : | G34: : | H34: : | I34: : | J34: : | K34: : | L34: : | M34: : | N34: : | O34: : | P34: : | Q34: : | R34: : | S34: : | T34: : | U34: : | V34: : | W34: : | X34: : | Y34: : | Z34: : | AA34: : | AB34: : | AC34: : | AD34: : | AE34: :
A35: Slovakia | B35: : | C35: : | D35: : | E35: : | F35: : | G35: : | H35: : | I35: : | J35: : | K35: : | L35: : | M35: : | N35: : | O35: : | P35: : | Q35: : | R35: : | S35: : | T35: : | U35: : | V35: : | W35: : | X35: : | Y35: : | Z35: : | AA35: : | AB35: : | AC35: : | AD35: : | AE35: :
A36: Finland | B36: 255393.4 | C36: 265449.6 | D36: 283751.3 | E36: 301894.9 | F36: 318284.3 | G36: 341343 | H36: 345431.2 | I36: 351614.8 | J36: 357756.6 | K36: 373393.5 | L36: 386627.3 | M36: 405942.1 | N36: 426307.8 | O36: 432669.3 | P36: 391073.4 | Q36: 399823.4 | R36: 411973.9 | S36: 408231.1 | T36: 402422.2 | U36: 401700 | V36: 399485.3 | W36: 411651.6 | X36: 425943.5 | Y36: 434330.3 | Z36: 444420 | AA36: 431990 | AB36: 445666.5 | AC36: 454745.2 | AD36: 446464.1 | AE36: 443943.8
A37: Sweden | B37: 501454.7 | C37: 509135.4 | D37: 528702 | E37: 553646.6 | F37: 576479.5 | G37: 608970.3 | H37: 616332.2 | I37: 620030.7 | J37: 626392.2 | K37: 651113.1 | L37: 672574.7 | M37: 705406.6 | N37: 734499 | O37: 732829.3 | P37: 685205 | Q37: 718050.1 | R37: 745355.8 | S37: 741296 | T37: 743492.3 | U37: 760224.5 | V37: 792436.7 | W37: 815989.9 | X37: 838715.5 | Y37: 860545 | Z37: 881384.3 | AA37: 859632.2 | AB37: 899121.9 | AC37: 927504 | AD37: 939102 | AE37: :
A38: Iceland | B38: 16158.3 | C38: 17199.7 | D38: 17992.9 | E38: 19336.5 | F38: 20270.5 | G38: 21351.6 | H38: 22156.2 | I38: 22017.7 | J38: 22638.7 | K38: 24221.5 | L38: 25339.8 | M38: 26158 | N38: 28173.2 | O38: 28670.4 | P38: 26675.3 | Q38: 25996.5 | R38: 26648.9 | S38: 27229.9 | T38: 28608.9 | U38: 29213 | V38: 30660.3 | W38: 32680.4 | X38: 34251.6 | Y38: 35992.1 | Z38: 36383.6 | AA38: 33103.9 | AB38: 35037.2 | AC38: 38789.5 | AD38: 40515.7 | AE38: :
A39: Liechtenstein | B39: : | C39: : | D39: : | E39: : | F39: : | G39: : | H39: : | I39: : | J39: : | K39: : | L39: : | M39: : | N39: : | O39: : | P39: : | Q39: : | R39: : | S39: : | T39: : | U39: : | V39: : | W39: : | X39: : | Y39: : | Z39: : | AA39: : | AB39: : | AC39: : | AD39: : | AE39: :
A40: Norway | B40: : | C40: : | D40: : | E40: : | F40: : | G40: : | H40: : | I40: : | J40: : | K40: : | L40: : | M40: : | N40: : | O40: : | P40: : | Q40: : | R40: : | S40: : | T40: : | U40: : | V40: : | W40: : | X40: : | Y40: : | Z40: : | AA40: : | AB40: : | AC40: : | AD40: : | AE40: :
A41: Switzerland | B41: 824681.7 | C41: 835602.3 | D41: 856289.9 | E41: 884356.1 | F41: 903157.5 | G41: 938070.8 | H41: 949628.9 | I41: 957940.6 | J41: 950731.9 | K41: 988243.2 | L41: 1021171.1 | M41: 1071463.4 | N41: 1123376.2 | O41: 1157212.2 | P41: 1135093.1 | Q41: 1159627.1 | R41: 1170393.4 | S41: 1195024.3 | T41: 1210353.9 | U41: 1242388.3 | V41: 1263867.9 | W41: 1285089.1 | X41: 1318600.7 | Y41: 1383257 | Z41: 1403306.4 | AA41: 1366731.3 | AB41: 1520890.5 | AC41: 1620640.7 | AD41: 1569843.2 | AE41: 1587671
A42: United Kingdom | B42: : | C42: : | D42: : | E42: : | F42: : | G42: : | H42: : | I42: : | J42: : | K42: : | L42: : | M42: : | N42: : | O42: : | P42: : | Q42: : | R42: : | S42: : | T42: : | U42: : | V42: : | W42: : | X42: : | Y42: : | Z42: : | AA42: : | AB42: : | AC42: : | AD42: : | AE42: :
A43: Bosnia and Herzegovina | B43: : | C43: : | D43: : | E43: : | F43: : | G43: : | H43: : | I43: : | J43: : | K43: : | L43: : | M43: : | N43: : | O43: : | P43: : | Q43: : | R43: : | S43: : | T43: : | U43: : | V43: : | W43: : | X43: : | Y43: : | Z43: : | AA43: : | AB43: : | AC43: : | AD43: : | AE43: :
A44: Montenegro | B44: : | C44: : | D44: : | E44: : | F44: : | G44: : | H44: : | I44: : | J44: : | K44: : | L44: : | M44: : | N44: : | O44: : | P44: : | Q44: : | R44: : | S44: : | T44: : | U44: : | V44: : | W44: : | X44: : | Y44: : | Z44: : | AA44: : | AB44: : | AC44: : | AD44: : | AE44: :
A45: North Macedonia | B45: : | C45: : | D45: : | E45: : | F45: : | G45: : | H45: : | I45: : | J45: : | K45: : | L45: : | M45: : | N45: : | O45: : | P45: : | Q45: : | R45: : | S45: : | T45: : | U45: : | V45: : | W45: : | X45: : | Y45: : | Z45: : | AA45: : | AB45: : | AC45: : | AD45: : | AE45: :
...

Sheet 2024 Adj Factor
A1: Data extracted on 30/01/2026 17:26:20 from [ESTAT]
A2: Dataset:
A3: Last updated:
A5: Time frequency
A6: Unit of measure
A7: Statistical classification of economic activities in the European Community (NACE Rev. 2)
A8: National accounts indicator (ESA 2010)
A10: TIME | B10: 2024
A11: Belgium | B11: =+IFERROR('Curr Prices'!$AE11/Q_chain_2020!$AE11,1) -> 1.2364719
A12: Bulgaria | B12: =+IFERROR('Curr Prices'!$AE12/Q_chain_2020!$AE12,1) -> 1
A13: Czechia | B13: =+IFERROR('Curr Prices'!$AE13/Q_chain_2020!$AE13,1) -> 1.318795
A14: Denmark | B14: =+IFERROR('Curr Prices'!$AE14/Q_chain_2020!$AE14,1) -> 1.1692328
A15: Germany | B15: =+IFERROR('Curr Prices'!$AE15/Q_chain_2020!$AE15,1) -> 1.2174057
A16: Estonia | B16: =+IFERROR('Curr Prices'!$AE16/Q_chain_2020!$AE16,1) -> 1.3460295
A17: Ireland | B17: =+IFERROR('Curr Prices'!$AE17/Q_chain_2020!$AE17,1) -> 1
A18: Greece | B18: =+IFERROR('Curr Prices'!$AE18/Q_chain_2020!$AE18,1) -> 1.2136327
A19: Spain | B19: =+IFERROR('Curr Prices'!$AE19/Q_chain_2020!$AE19,1) -> 1
A20: France | B20: =+IFERROR('Curr Prices'!$AE20/Q_chain_2020!$AE20,1) -> 1.1365513
A21: Croatia | B21: =+IFERROR('Curr Prices'!$AE21/Q_chain_2020!$AE21,1) -> 1
A22: Italy | B22: =+IFERROR('Curr Prices'!$AE22/Q_chain_2020!$AE22,1) -> 1
... A49: Kosovo* | B49: =+IFERROR('Curr Prices'!$AE49/Q_chain_2020!$AE49,1) -> 1
A51: Special value
A52: :
A53: Observation flags:
A54: b
A55: p

Sheet Curr Prices
A1: Data extracted on 30/01/2026 16:56:35 from [ESTAT]
A2: Dataset:
A3: Last updated:
A5: Time frequency
A6: Unit of measure
A7: Statistical classification of economic activities in the European Community (NACE Rev. 2)
A8: National accounts indicator (ESA 2010)
A10: TIME | B10: 1995 | C10: 1996 | D10: 1997 | E10: 1998 | F10: 1999 | G10: 2000 | H10: 2001 | I10: 2002 | J10: 2003 | K10: 2004 | L10: 2005 | M10: 2006 | N10: 2007 | O10: 2008 | P10: 2009 | Q10: 2010 | R10: 2011 | S10: 2012 | T10: 2013 | U10: 2014 | V10: 2015 | W10: 2016 | X10: 2017 | Y10: 2018 | Z10: 2019 | AA10: 2020 | AB10: 2021 | AC10: 2022 | AD10: 2023 | AE10: 2024
A11: Belgium | B11: 435631.7 | C11: 437580.2 | D11: 450177.6 | E11: 469496 | F11: 495898.5 | G11: 531625.1 | H11: 552759.4 | I11: 554917.3 | J11: 560163.2 | K11: 596124.5 | L11: 627644.9 | M11: 672337.3 | N11: 714294.2 | O11: 748382.9 | P11: 698820.4 | Q11: 753636.2 | R11: 810495.9 | S11: 827307.3 | T11: 829212.5 | U11: 842493.9 | V11: 851794.2 | W11: 874749.2 | X11: 918111.2 | Y11: 959974.2 | Z11: 996037.6 | AA11: 940992.2 | AB11: 1093235.2 | AC11: 1239048.8 | AD11: 1266093.6 | AE11: 1291294.1
A12: Bulgaria | B12: 26401 | C12: 18128.1 | D12: 21181.5 | E12: 26727 | F12: 24878.8 | G12: 28945.6 | H12: 32614.4 | I12: 35139 | J12: 38228.6 | K12: 44764 | L12: 52007.1 | M12: 61037.3 | N12: 73357.7 | O12: 83038.3 | P12: 78573.1 | Q12: 79100.9 | R12: 87229.5 | S12: 89273.3 | T12: 86835.6 | U12: 92181.3 | V12: 96466.7 | W12: 96102.3 | X12: 105334.4 | Y12: 114437 | Z12: 122472.3 | AA12: 121840.5 | AB12: 142869.6 | AC12: 181107.1 | AD12: 186922.5 | AE12: 199793.7
A13: Czechia | B13: 100603.4 | C13: 114187.6 | D13: 121777.5 | E13: 131468.6 | F13: 132446.5 | G13: 150001 | H13: 170366.4 | I13: 194577.2 | J13: 202800.2 | K13: 222404.8 | L13: 252930.3 | M13: 296525.6 | N13: 333937.2 | O13: 386805.1 | P13: 336540.8 | Q13: 369796 | R13: 397457.6 | S13: 385671.5 | T13: 374629.4 | U13: 372688.7 | V13: 392787.6 | W13: 403907.5 | X13: 445762.9 | Y13: 484885.1 | Z13: 505920.5 | AA13: 474024.3 | AB13: 546775.7 | AC13: 662320.8 | AD13: 706405.2 | AE13: 705976.7
A14: Denmark | B14: 230019.8 | C14: 239327.1 | D14: 248135.3 | E14: 255378.8 | F14: 270984.9 | G14: 295904.6 | H14: 311351.3 | I14: 319094.1 | J14: 322326.4 | K14: 335873.2 | L14: 362981 | M14: 392511.3 | N14: 415953.2 | O14: 438721.7 | P14: 404759.6 | Q14: 419961.1 | R14: 438363.1 | S14: 453169 | T14: 456335 | U14: 466934.6 | V14: 478197.7 | W14: 492163.6 | X14: 516314 | Y14: 532646.8 | Z14: 547927 | AA14: 544046.5 | AB14: 606614.2 | AC14: 706280.6 | AD14: 686495.7 | AE14: 714098.4
A15: Germany | B15: 3363289.1 | C15: 3353881.3 | D15: 3352643.3 | E15: 3457810.3 | F15: 3604164 | G15: 3785177 | H15: 3901673 | I15: 3896441 | J15: 3963842 | K15: 4093053 | L15: 4229317 | M15: 4473332 | N15: 4723700 | O15: 4891666 | P15: 4555414 | Q15: 4875375 | R15: 5218900 | S15: 5259518 | T15: 5307190 | U15: 5484187 | V15: 5617824 | W15: 5765492 | X15: 6056270 | Y15: 6317725 | Z15: 6491932 | AA15: 6329832 | AB15: 6856211 | AC15: 7817428 | AD15: 8127610 | AE15: 8190679
A16: Estonia | B16: 6184.2 | C16: 7514.6 | D16: 9282.4 | E16: 10523.7 | F16: 10868.4 | G16: 12760.7 | H16: 14597.5 | I16: 16202.2 | J16: 17801.7 | K16: 20023.5 | L16: 23113 | M16: 27203 | N16: 32154.3 | O16: 33136.6 | P16: 26405.9 | Q16: 29429.1 | R16: 34476.9 | S16: 37094 | T16: 39250.9 | U16: 40669.4 | V16: 41229.7 | W16: 43024.2 | X16: 47336.3 | Y16: 51646.7 | Z16: 55399.3 | AA16: 53980.6 | AB16: 62643.7 | AC16: 75694.6 | AD16: 77033.1 | AE16: 78365.3
A17: Ireland | B17: 110175.2 | C17: 122121.4 | D17: 150984.1 | E17: 169828.1 | F17: 191831.3 | G17: 223420.3 | H17: 253658.1 | I17: 272849.8 | J17: 294245.2 | K17: 314754.7 | L17: 345133.1 | M17: 386387.5 | N17: 419441.3 | O17: 421614.9 | P17: 373054.1 | Q17: 350768.4 | R17: 333306.5 | S17: 373970.9 | T17: 389143.6 | U17: 417385.2 | V17: 517592.9 | W17: 533200.6 | X17: 575036.7 | Y17: 637837.3 | Z17: 684497.2 | AA17: 706976.3 | AB17: 856316.7 | AC17: 1007801.3 | AD17: 1020302 | AE17: 1127871.2
A18: Greece | B18: 182994.8 | C18: 197461 | D18: 209804.5 | E18: 212670.3 | F18: 228195.4 | G18: 238662.8 | H18: 252968.4 | I18: 271765.2 | J18: 290199.5 | K18: 314690.4 | L18: 322951.9 | M18: 356498.7 | N18: 379353.6 | O18: 386992.6 | P18: 375014.2 | Q18: 354705.5 | R18: 323298.8 | S18: 304175.6 | T18: 297188.9 | U18: 292166.2 | V18: 289314.4 | W18: 278659.7 | X18: 288662.7 | Y18: 298369.5 | Z18: 308200.4 | AA18: 268864 | AB18: 311808.9 | AC18: 379821.5 | AD18: 398175.9 | AE18: 413353.1
A19: Spain | B19: 832054.4 | C19: 900963.8 | D19: 934207.6 | E19: 995474.3 | F19: 1085147 | G19: 1210179 | H19: 1315527 | I19: 1428956 | J19: 1531685 | K19: 1656301 | L19: 1819373 | M19: 2002881 | N19: 2151601 | O19: 2182913 | P19: 1994019 | Q19: 1973881 | R19: 1966146 | S19: 1897530 | T19: 1852544 | U19: 1884381 | V19: 1939466 | W19: 1969898 | X19: 2077118 | Y19: 2171029 | Z19: 2255859 | AA19: 2030323 | AB19: 2280636 | AC19: 2664587 | AD19: 2787473 | AE19: 2946682
A20: France | B20: 2079657.8 | C20: 2135117.6 | D20: 2181019.8 | E20: 2282387 | F20: 2413850.8 | G20: 2622461.7 | H20: 2743180 | I20: 2802455.5 | J20: 2849038 | K20: 2981543.3 | L20: 3124467.8 | M20: 3301823.7 | N20: 3480607.2 | O20: 3589021.3 | P20: 3405041.2 | Q20: 3562583 | R20: 3710048.8 | S20: 3757021.1 | T20: 3782756.6 | U20: 3824657 | V20: 3874959 | W20: 3916430.5 | X20: 4081058.4 | Y20: 4218828.5 | Z20: 4351548.9 | AA20: 4075011.5 | AB20: 4520881.4 | AC20: 5111526.8 | AD20: 5309979.5 | AE20: 5386541.6
A21: Croatia | B21: 32396.8 | C21: 35281 | D21: 39704.8 | E21: 39475 | F21: 37954.8 | G21: 40104.1 | H21: 44063.7 | I21: 49086.3 | J21: 53556.1 | K21: 58924.5 | L21: 65293.9 | M21: 72846.2 | N21: 80016.7 | O21: 86574.4 | P21: 79511.2 | Q21: 78010.4 | R21: 78937.2 | S21: 77220 | T21: 75435.3 | U21: 74268.1 | V21: 75870.2 | W21: 79248.5 | X21: 84003.8 | Y21: 89307.3 | Z21: 92202.7 | AA21: 84455.6 | AB21: 98916.1 | AC21: 119401 | AD21: 135621.5 | AE21: 144486.1
... A37: Sweden | B37: 368544.3 | C37: 412644.5 | D37: 429720.5 | E37: 437338 | F37: 466188.7 | G37: 525677.2 | H37: 500504.4 | I37: 515703 | J37: 530626 | K37: 560594.5 | L37: 579548.5 | M37: 624812.2 | N37: 670604.1 | O37: 670699.6 | P37: 573297.2 | Q37: 681498.6 | R37: 759859 | S37: 791822.1 | T37: 800335.7 | U37: 789519.4 | V37: 810028.7 | W37: 827849.4 | X37: 858849.9 | Y37: 855808.4 | Z37: 869292.4 | AA37: 859632.2 | AB37: 971889.9 | AC37: 1052123.9 | AD37: 1033078.5 | AE37: 1075981.4
A38: Iceland | B38: 9106.5 | C38: 10069.2 | D38: 11054.8 | E38: 12429.3 | F38: 13986.6 | G38: 16843.5 | H38: 15831.3 | I38: 17006.6 | J38: 17707.6 | K38: 19716.4 | L38: 24460 | M38: 25887.6 | N38: 29963.9 | O38: 20543 | P38: 16864.9 | Q38: 19168.7 | R38: 20614.8 | S38: 22010.8 | T38: 22946.6 | U38: 25254.2 | V38: 29222.1 | W38: 34151.6 | X38: 39923.8 | Y38: 40805.5 | Z38: 38995.9 | AA38: 33103.9 | AB38: 39865.7 | AC38: 50697.2 | AD38: 54055.9 | AE38: :
A39: Liechtenstein | B39: : | C39: : | D39: : | E39: : | F39: : | G39: : | H39: : | I39: : | J39: : | K39: : | L39: : | M39: : | N39: : | O39: : | P39: : | Q39: : | R39: : | S39: : | T39: 11935.2 | U39: 12611.1 | V39: 13813.2 | W39: 15296.4 | X39: 14044 | Y39: 14288.2 | Z39: 14844 | AA39: 14050.5 | AB39: 15376 | AC39: 19622.3 | AD39: : | AE39: :
A40: Norway | B40: 190954.9 | C40: 210453.8 | D40: 235039.5 | E40: 233423.4 | F40: 255701.5 | G40: 299346.8 | H40: 316678.8 | I40: 340756.5 | J40: 330086.2 | K40: 343823.9 | L40: 398552.9 | M40: 445406.6 | N40: 485865.7 | O40: 528015.7 | P40: 462910.6 | Q40: 527903.8 | R40: 585819.7 | S40: 647598.4 | T40: 645687.7 | U40: 625388.4 | V40: 583232.5 | W40: 557733.7 | X40: 586488.8 | Y40: 614515.4 | Z40: 614230.1 | AA40: 545143.7 | AB40: 687163.8 | AC40: 876587.5 | AD40: 736388 | AE40: 740528.4
A41: Switzerland | B41: 531318.8 | C41: 532674.3 | D41: 519937.3 | E41: 542393.9 | F41: 560182.3 | G41: 601154.8 | H41: 633334.9 | I41: 659186.1 | J41: 638594.8 | K41: 655735.2 | L41: 680197.7 | M41: 713784.2 | N41: 732159.9 | O41: 799076 | P41: 820626.2 | Q41: 920985.4 | R41: 1047296.9 | S41: 1094687.8 | T41: 1087195.6 | U41: 1118684.2 | V41: 1263984.1 | W41: 1254465.4 | X41: 1266488.7 | Y41: 1282274 | Z41: 1358918.4 | AA41: 1347336.8 | AB41: 1514649.3 | AC41: 1795339.9 | AD41: 1868804.1 | AE41: :
A42: United Kingdom | B42: 1729300.5 | C42: 1880723.8 | D42: 2325497.6 | E42: 2504200 | F42: 2671635.2 | G42: 3038795.4 | H42: 3107739.6 | I42: 3203600.3 | J42: 3056198.8 | K42: 3289218.5 | L42: 3420672.7 | M42: 3684785.8 | N42: 3890988.4 | O42: 3458468.1 | P42: 3024495.5 | Q42: 3244557.3 | R42: 3317768.6 | S42: 3649882.2 | T42: 3632427.1 | U42: 3954330.6 | V42: 4489000.3 | W42: 4111656.2 | X42: 4007594.6 | Y42: 4123911.8 | Z42: 4285954.2 | AA42: : | AB42: : | AC42: : | AD42: : | AE42: :
A43: Bosnia and Herzegovina | B43: : | C43: : | D43: : | E43: : | F43: : | G43: 10535.3 | H43: 11056.4 | I43: 11940.5 | J43: 12462.1 | K43: 13796.3 | L43: 15972.9 | M43: 17258.1 | N43: 19635.6 | O43: 22904 | P43: 21173 | Q43: 22287.3 | R43: 23661.9 | S43: 23666.1 | T43: 24149.4 | U43: 24478.3 | V43: 25346.9 | W43: 26585.6 | X43: 28171 | Y43: 29392 | Z43: 30233.6 | AA43: 28892.9 | AB43: 32745.1 | AC43: 39106.2 | AD43: 41433.7 | AE43: :
A44: Montenegro | B44: : | C44: : | D44: : | E44: : | F44: : | G44: : | H44: : | I44: : | J44: : | K44: : | L44: : | M44: 4372.2 | N44: 5208.9 | O44: 6459.8 | P44: 4641 | Q44: 5204.2 | R44: 5380.4 | S44: 5300.4 | T44: 5477.4 | U44: 5517.4 | V44: 5831.8 | W44: 6396.2 | X44: 7094.4 | Y44: 7780.9 | Z44: 8155.7 | AA44: 6904.5 | AB44: 7965.8 | AC44: 9553.5 | AD44: 11191.6 | AE44: 12276.8
A45: North Macedonia | B45: : | C45: : | D45: : | E45: : | F45: : | G45: 8291.7 | H45: 8194.6 | I45: 8103.6 | J45: 8455.3 | K45: 9198.8 | L45: 10070.8 | M45: 11156.9 | N45: 12667.9 | O45: 14250.8 | P45: 13114.2 | Q45: 13748.6 | R45: 14633.1 | S45: 14457.7 | T45: 15103.4 | U45: 15941.4 | V45: 16917.3 | W45: 17831.6 | X45: 18755.2 | Y45: 20500 | Z45: 21475.9 | AA45: 20272.1 | AB45: 23087.1 | AC45: : | AD45: : | AE45: :
A46: Albania | B46: 3489.4 | C46: 3951.4 | D46: 3047.4 | E46: 3557.8 | F46: 4822.6 | G46: 6036.4 | H46: 7038 | I46: 7429.1 | J46: 7664.9 | K46: 9131.6 | L46: 10177.4 | M46: 11124.4 | N46: 12454.2 | O46: 14292 | P46: 14152.2 | Q46: 14026.5 | R46: 14701.2 | S46: 14956.2 | T46: 15370.3 | U46: 15493.8 | V46: 16002.8 | W46: 16757.6 | X46: 17808.7 | Y46: 19469.4 | Z46: 20504.6 | AA46: 19907.4 | AB46: 22803 | AC46: 26395.2 | AD46: 31394.8 | AE46: 36326.5
A47: Serbia | B47: 76554 | C47: 54182.2 | D47: 68422.1 | E47: 54253.4 | F47: 56315 | G47: 87708.1 | H47: 40179.3 | I47: 47813 | J47: 50146.8 | K47: 53306.3 | L47: 57273.7 | M47: 66056.6 | N47: 79027.4 | O47: 86018.9 | P47: 72130.7 | Q47: 71830.4 | R47: 80930.6 | S47: 76624.9 | T47: 82522.1 | U47: 77882.7 | V47: 79322.8 | W47: 81055.2 | X47: 86428.8 | Y47: 94110.1 | Z47: 101333.2 | AA47: 101133.6 | AB47: 116756.8 | AC47: 134001.3 | AD47: 154012.3 | AE47: 167804.8
A48: Türkiye | B48: : | C48: : | D48: : | E48: : | F48: : | G48: : | H48: : | I48: : | J48: : | K48: : | L48: : | M48: : | N48: : | O48: : | P48: : | Q48: : | R48: : | S48: : | T48: : | U48: : | V48: : | W48: : | X48: : | Y48: : | Z48: : | AA48: : | AB48: : | AC48: : | AD48: 2032369.2 | AE48: :
A49: Kosovo* | B49: : | C49: : | D49: : | E49: : | F49: : | G49: : | H49: : | I49: : | J49: : | K49: : | L49: : | M49: : | N49: : | O49: : | P49: : | Q49: : | R49: : | S49: : | T49: : | U49: : | V49: : | W49: : | X49: : | Y49: : | Z49: : | AA49: : | AB49: : | AC49: : | AD49: : | AE49: :
A51: Special value
A52: :
A53: Observation flags:
A54: b
A55: e
A56: p

Sheet 2024 Prices
B1: 1995 | C1: 1996 | D1: 1997 | E1: 1998 | F1: 1999 | G1: 2000 | H1: 2001 | I1: 2002 | J1: 2003 | K1: 2004 | L1: 2005 | M1: 2006 | N1: 2007 | O1: 2008 | P1: 2009 | Q1: 2010 | R1: 2011 | S1: 2012 | T1: 2013 | U1: 2014 | V1: 2015 | W1: 2016 | X1: 2017 | Y1: 2018 | Z1: 2019 | AA1: 2020 | AB1: 2021 | AC1: 2022 | AD1: 2023 | AE1: 2024
A2: Belgium | B2: =+IFERROR(_xlfn.XLOOKUP($A2,'Curr Prices'!$A$11:$A$49,'Curr Prices'!B$11:B$49,,0)*_xlfn.XLOOKUP($A2,'2024 Adj Factor'!$A$11:$A$49,'2024 Adj Factor'!$B$11:$B$49,,0),0) -> 538646.36 | C2: =+IFERROR(_xlfn.XLOOKUP($A2,'Curr Prices'!$A$11:$A$49,'Curr Prices'!C$11:C$49,,0)*_xlfn.XLOOKUP($A2,'2024 Adj Factor'!$A$11:$A$49,'2024 Adj Factor'!$B$11:$B$49,,0),0) -> 541055.62 | D2: =+IFERROR(_xlfn.XLOOKUP($A2,'Curr Prices'!$A$11:$A$49,'Curr Prices'!D$11:D$49,,0)*_xlfn.XLOOKUP($A2,'2024 Adj Factor'!$A$11:$A$49,'2024 Adj Factor'!$B$11:$B$49,,0),0) -> 556631.95 | E2: =+IFERROR(_xlfn.XLOOKUP($A2,'Curr Prices'!$A$11:$A$49,'Curr Prices'!E$11:E$49,,0)*_xlfn.XLOOKUP($A2,'2024 Adj Factor'!$A$11:$A$49,'2024 Adj Factor'!$B$11:$B$49,,0),0) -> 580518.61 | F2: =+IFERROR(_xlfn.XLOOKUP($A2,'Curr Prices'!$A$11:$A$49,'Curr Prices'!F$11:F$49,,0)*_xlfn.XLOOKUP($A2,'2024 Adj Factor'!$A$11:$A$49,'2024 Adj Factor'!$B$11:$B$49,,0),0) -> 613164.56 | G2: =+IFERROR(_xlfn.XLOOKUP($A2,'Curr Prices'!$A$11:$A$49,'Curr Prices'!G$11:G$49,,0)*_xlfn.XLOOKUP($A2,'2024 Adj Factor'!$A$11:$A$49,'2024 Adj Factor'!$B$11:$B$49,,0),0) -> 657339.5 | H2: =+IFERROR(_xlfn.XLOOKUP($A2,'Curr Prices'!$A$11:$A$49,'Curr Prices'!H$11:H$49,,0)*_xlfn.XLOOKUP($A2,'2024 Adj Factor'!$A$11:$A$49,'2024 Adj Factor'!$B$11:$B$49,,0),0) -> 683471.47 | I2: =+IFERROR(_xlfn.XLOOKUP($A2,'Curr Prices'!$A$11:$A$49,'Curr Prices'!I$11:I$49,,0)*_xlfn.XLOOKUP($A2,'2024 Adj Factor'!$A$11:$A$49,'2024 Adj Factor'!$B$11:$B$49,,0),0) -> 686139.65 | ... AE2: =+IFERROR(_xlfn.XLOOKUP($A2,'Curr Prices'!$A$11:$A$49,'Curr Prices'!AE$11:AE$49,,0)*_xlfn.XLOOKUP($A2,'2024 Adj Factor'!$A$11:$A$49,'2024 Adj Factor'!$B$11:$B$49,,0),0) -> 1596648.9
A3: Bulgaria | B3: =+IFERROR(_xlfn.XLOOKUP($A3,'Curr Prices'!$A$11:$A$49,'Curr Prices'!B$11:B$49,,0)*_xlfn.XLOOKUP($A3,'2024 Adj Factor'!$A$11:$A$49,'2024 Adj Factor'!$B$11:$B$49,,0),0) -> 26401 | C3: =+IFERROR(_xlfn.XLOOKUP($A3,'Curr Prices'!$A$11:$A$49,'Curr Prices'!C$11:C$49,,0)*_xlfn.XLOOKUP($A3,'2024 Adj Factor'!$A$11:$A$49,'2024 Adj Factor'!$B$11:$B$49,,0),0) -> 18128.1 | D3: =+IFERROR(_xlfn.XLOOKUP($A3,'Curr Prices'!$A$11:$A$49,'Curr Prices'!D$11:D$49,,0)*_xlfn.XLOOKUP($A3,'2024 Adj Factor'!$A$11:$A$49,'2024 Adj Factor'!$B$11:$B$49,,0),0) -> 21181.5 | E3: =+IFERROR(_xlfn.XLOOKUP($A3,'Curr Prices'!$A$11:$A$49,'Curr Prices'!E$11:E$49,,0)*_xlfn.XLOOKUP($A3,'2024 Adj Factor'!$A$11:$A$49,'2024 Adj Factor'!$B$11:$B$49,,0),0) -> 26727 | F3: =+IFERROR(_xlfn.XLOOKUP($A3,'Curr Prices'!$A$11:$A$49,'Curr Prices'!F$11:F$49,,0)*_xlfn.XLOOKUP($A3,'2024 Adj Factor'!$A$11:$A$49,'2024 Adj Factor'!$B$11:$B$49,,0),0) -> 24878.8 | G3: =+IFERROR(_xlfn.XLOOKUP($A3,'Curr Prices'!$A$11:$A$49,'Curr Prices'!G$11:G$49,,0)*_xlfn.XLOOKUP($A3,'2024 Adj Factor'!$A$11:$A$49,'2024 Adj Factor'!$B$11:$B$49,,0),0) -> 28945.6 | H3: =+IFERROR(_xlfn.XLOOKUP($A3,'Curr Prices'!$A$11:$A$49,'Curr Prices'!H$11:H$49,,0)*_xlfn.XLOOKUP($A3,'2024 Adj Factor'!$A$11:$A$49,'2024 Adj Factor'!$B$11:$B$49,,0),0) -> 32614.4 | I3: =+IFERROR(_xlfn.XLOOKUP($A3,'Curr Prices'!$A$11:$A$49,'Curr Prices'!I$11:I$49,,0)*_xlfn.XLOOKUP($A3,'2024 Adj Factor'!$A$11:$A$49,'2024 Adj Factor'!$B$11:$B$49,,0),0) -> 35139 | ... AE3: =+IFERROR(_xlfn.XLOOKUP($A3,'Curr Prices'!$A$11:$A$49,'Curr Prices'!AE$11:AE$49,,0)*_xlfn.XLOOKUP($A3,'2024 Adj Factor'!$A$11:$A$49,'2024 Adj Factor'!$B$11:$B$49,,0),0) -> 199793.7
A4: Czechia | B4: =+IFERROR(_xlfn.XLOOKUP($A4,'Curr Prices'!$A$11:$A$49,'Curr Prices'!B$11:B$49,,0)*_xlfn.XLOOKUP($A4,'2024 Adj Factor'!$A$11:$A$49,'2024 Adj Factor'!$B$11:$B$49,,0),0) -> 132675.26 | C4: =+IFERROR(_xlfn.XLOOKUP($A4,'Curr Prices'!$A$11:$A$49,'Curr Prices'!C$11:C$49,,0)*_xlfn.XLOOKUP($A4,'2024 Adj Factor'!$A$11:$A$49,'2024 Adj Factor'!$B$11:$B$49,,0),0) -> 150590.04 | D4: =+IFERROR(_xlfn.XLOOKUP($A4,'Curr Prices'!$A$11:$A$49,'Curr Prices'!D$11:D$49,,0)*_xlfn.XLOOKUP($A4,'2024 Adj Factor'!$A$11:$A$49,'2024 Adj Factor'!$B$11:$B$49,,0),0) -> 160599.56 | E4: =+IFERROR(_xlfn.XLOOKUP($A4,'Curr Prices'!$A$11:$A$49,'Curr Prices'!E$11:E$49,,0)*_xlfn.XLOOKUP($A4,'2024 Adj Factor'!$A$11:$A$49,'2024 Adj Factor'!$B$11:$B$49,,0),0) -> 173380.14 | F4: =+IFERROR(_xlfn.XLOOKUP($A4,'Curr Prices'!$A$11:$A$49,'Curr Prices'!F$11:F$49,,0)*_xlfn.XLOOKUP($A4,'2024 Adj Factor'!$A$11:$A$49,'2024 Adj Factor'!$B$11:$B$49,,0),0) -> 174669.79 | G4: =+IFERROR(_xlfn.XLOOKUP($A4,'Curr Prices'!$A$11:$A$49,'Curr Prices'!G$11:G$49,,0)*_xlfn.XLOOKUP($A4,'2024 Adj Factor'!$A$11:$A$49,'2024 Adj Factor'!$B$11:$B$49,,0),0) -> 197820.57 | H4: =+IFERROR(_xlfn.XLOOKUP($A4,'Curr Prices'!$A$11:$A$49,'Curr Prices'!H$11:H$49,,0)*_xlfn.XLOOKUP($A4,'2024 Adj Factor'!$A$11:$A$49,'2024 Adj Factor'!$B$11:$B$49,,0),0) -> 224678.36 | I4: =+IFERROR(_xlfn.XLOOKUP($A4,'Curr Prices'!$A$11:$A$49,'Curr Prices'!I$11:I$49,,0)*_xlfn.XLOOKUP($A4,'2024 Adj Factor'!$A$11:$A$49,'2024 Adj Factor'!$B$11:$B$49,,0),0) -> 256607.45 | ... AE4: =+IFERROR(_xlfn.XLOOKUP($A4,'Curr Prices'!$A$11:$A$49,'Curr Prices'!AE$11:AE$49,,0)*_xlfn.XLOOKUP($A4,'2024 Adj Factor'!$A$11:$A$49,'2024 Adj Factor'!$B$11:$B$49,,0),0) -> 931038.57
A5: Denmark | B5: =+IFERROR(_xlfn.XLOOKUP($A5,'Curr Prices'!$A$11:$A$49,'Curr Prices'!B$11:B$49,,0)*_xlfn.XLOOKUP($A5,'2024 Adj Factor'!$A$11:$A$49,'2024 Adj Factor'!$B$11:$B$49,,0),0) -> 268946.69 | C5: =+IFERROR(_xlfn.XLOOKUP($A5,'Curr Prices'!$A$11:$A$49,'Curr Prices'!C$11:C$49,,0)*_xlfn.XLOOKUP($A5,'2024 Adj Factor'!$A$11:$A$49,'2024 Adj Factor'!$B$11:$B$49,,0),0) -> 279829.09 | D5: =+IFERROR(_xlfn.XLOOKUP($A5,'Curr Prices'!$A$11:$A$49,'Curr Prices'!D$11:D$49,,0)*_xlfn.XLOOKUP($A5,'2024 Adj Factor'!$A$11:$A$49,'2024 Adj Factor'!$B$11:$B$49,,0),0) -> 290127.93 | E5: =+IFERROR(_xlfn.XLOOKUP($A5,'Curr Prices'!$A$11:$A$49,'Curr Prices'!E$11:E$49,,0)*_xlfn.XLOOKUP($A5,'2024 Adj Factor'!$A$11:$A$49,'2024 Adj Factor'!$B$11:$B$49,,0),0) -> 298597.27 | F5: =+IFERROR(_xlfn.XLOOKUP($A5,'Curr Prices'!$A$11:$A$49,'Curr Prices'!F$11:F$49,,0)*_xlfn.XLOOKUP($A5,'2024 Adj Factor'!$A$11:$A$49,'2024 Adj Factor'!$B$11:$B$49,,0),0) -> 316844.43 | G5: =+IFERROR(_xlfn.XLOOKUP($A5,'Curr Prices'!$A$11:$A$49,'Curr Prices'!G$11:G$49,,0)*_xlfn.XLOOKUP($A5,'2024 Adj Factor'!$A$11:$A$49,'2024 Adj Factor'!$B$11:$B$49,,0),0) -> 345981.36 | H5: =+IFERROR(_xlfn.XLOOKUP($A5,'Curr Prices'!$A$11:$A$49,'Curr Prices'!H$11:H$49,,0)*_xlfn.XLOOKUP($A5,'2024 Adj Factor'!$A$11:$A$49,'2024 Adj Factor'!$B$11:$B$49,,0),0) -> 364042.15 | I5: =+IFERROR(_xlfn.XLOOKUP($A5,'Curr Prices'!$A$11:$A$49,'Curr Prices'!I$11:I$49,,0)*_xlfn.XLOOKUP($A5,'2024 Adj Factor'!$A$11:$A$49,'2024 Adj Factor'!$B$11:$B$49,,0),0) -> 373095.28 | ... AE5: =+IFERROR(_xlfn.XLOOKUP($A5,'Curr Prices'!$A$11:$A$49,'Curr Prices'!AE$11:AE$49,,0)*_xlfn.XLOOKUP($A5,'2024 Adj Factor'!$A$11:$A$49,'2024 Adj Factor'!$B$11:$B$49,,0),0) -> 834947.26
A6: Germany | B6: =+IFERROR(_xlfn.XLOOKUP($A6,'Curr Prices'!$A$11:$A$49,'Curr Prices'!B$11:B$49,,0)*_xlfn.XLOOKUP($A6,'2024 Adj Factor'!$A$11:$A$49,'2024 Adj Factor'!$B$11:$B$49,,0),0) -> 4094487.2 | C6: =+IFERROR(_xlfn.XLOOKUP($A6,'Curr Prices'!$A$11:$A$49,'Curr Prices'!C$11:C$49,,0)*_xlfn.XLOOKUP($A6,'2024 Adj Factor'!$A$11:$A$49,'2024 Adj Factor'!$B$11:$B$49,,0),0) -> 4083034.1 | D6: =+IFERROR(_xlfn.XLOOKUP($A6,'Curr Prices'!$A$11:$A$49,'Curr Prices'!D$11:D$49,,0)*_xlfn.XLOOKUP($A6,'2024 Adj Factor'!$A$11:$A$49,'2024 Adj Factor'!$B$11:$B$49,,0),0) -> 4081526.9 | E6: =+IFERROR(_xlfn.XLOOKUP($A6,'Curr Prices'!$A$11:$A$49,'Curr Prices'!E$11:E$49,,0)*_xlfn.XLOOKUP($A6,'2024 Adj Factor'!$A$11:$A$49,'2024 Adj Factor'!$B$11:$B$49,,0),0) -> 4209557.8 | F6: =+IFERROR(_xlfn.XLOOKUP($A6,'Curr Prices'!$A$11:$A$49,'Curr Prices'!F$11:F$49,,0)*_xlfn.XLOOKUP($A6,'2024 Adj Factor'!$A$11:$A$49,'2024 Adj Factor'!$B$11:$B$49,,0),0) -> 4387729.7 | G6: =+IFERROR(_xlfn.XLOOKUP($A6,'Curr Prices'!$A$11:$A$49,'Curr Prices'!G$11:G$49,,0)*_xlfn.XLOOKUP($A6,'2024 Adj Factor'!$A$11:$A$49,'2024 Adj Factor'!$B$11:$B$49,,0),0) -> 4608095.9 | H6: =+IFERROR(_xlfn.XLOOKUP($A6,'Curr Prices'!$A$11:$A$49,'Curr Prices'!H$11:H$49,,0)*_xlfn.XLOOKUP($A6,'2024 Adj Factor'!$A$11:$A$49,'2024 Adj Factor'!$B$11:$B$49,,0),0) -> 4749918.8 | I6: =+IFERROR(_xlfn.XLOOKUP($A6,'Curr Prices'!$A$11:$A$49,'Curr Prices'!I$11:I$49,,0)*_xlfn.XLOOKUP($A6,'2024 Adj Factor'!$A$11:$A$49,'2024 Adj Factor'!$B$11:$B$49,,0),0) -> 4743549.3 | ... AE6: =+IFERROR(_xlfn.XLOOKUP($A6,'Curr Prices'!$A$11:$A$49,'Curr Prices'!AE$11:AE$49,,0)*_xlfn.XLOOKUP($A6,'2024 Adj Factor'!$A$11:$A$49,'2024 Adj Factor'!$B$11:$B$49,,0),0) -> 9971379
A7: Estonia | B7: =+IFERROR(_xlfn.XLOOKUP($A7,'Curr Prices'!$A$11:$A$49,'Curr Prices'!B$11:B$49,,0)*_xlfn.XLOOKUP($A7,'2024 Adj Factor'!$A$11:$A$49,'2024 Adj Factor'!$B$11:$B$49,,0),0) -> 8324.1157 | C7: =+IFERROR(_xlfn.XLOOKUP($A7,'Curr Prices'!$A$11:$A$49,'Curr Prices'!C$11:C$49,,0)*_xlfn.XLOOKUP($A7,'2024 Adj Factor'!$A$11:$A$49,'2024 Adj Factor'!$B$11:$B$49,,0),0) -> 10114.873 | D7: =+IFERROR(_xlfn.XLOOKUP($A7,'Curr Prices'!$A$11:$A$49,'Curr Prices'!D$11:D$49,,0)*_xlfn.XLOOKUP($A7,'2024 Adj Factor'!$A$11:$A$49,'2024 Adj Factor'!$B$11:$B$49,,0),0) -> 12494.384 | E7: =+IFERROR(_xlfn.XLOOKUP($A7,'Curr Prices'!$A$11:$A$49,'Curr Prices'!E$11:E$49,,0)*_xlfn.XLOOKUP($A7,'2024 Adj Factor'!$A$11:$A$49,'2024 Adj Factor'!$B$11:$B$49,,0),0) -> 14165.211 | F7: =+IFERROR(_xlfn.XLOOKUP($A7,'Curr Prices'!$A$11:$A$49,'Curr Prices'!F$11:F$49,,0)*_xlfn.XLOOKUP($A7,'2024 Adj Factor'!$A$11:$A$49,'2024 Adj Factor'!$B$11:$B$49,,0),0) -> 14629.187 | G7: =+IFERROR(_xlfn.XLOOKUP($A7,'Curr Prices'!$A$11:$A$49,'Curr Prices'!G$11:G$49,,0)*_xlfn.XLOOKUP($A7,'2024 Adj Factor'!$A$11:$A$49,'2024 Adj Factor'!$B$11:$B$49,,0),0) -> 17176.279 | H7: =+IFERROR(_xlfn.XLOOKUP($A7,'Curr Prices'!$A$11:$A$49,'Curr Prices'!H$11:H$49,,0)*_xlfn.XLOOKUP($A7,'2024 Adj Factor'!$A$11:$A$49,'2024 Adj Factor'!$B$11:$B$49,,0),0) -> 19648.666 | I7: =+IFERROR(_xlfn.XLOOKUP($A7,'Curr Prices'!$A$11:$A$49,'Curr Prices'!I$11:I$49,,0)*_xlfn.XLOOKUP($A7,'2024 Adj Factor'!$A$11:$A$49,'2024 Adj Factor'!$B$11:$B$49,,0),0) -> 21808.639 | ... AE7: =+IFERROR(_xlfn.XLOOKUP($A7,'Curr Prices'!$A$11:$A$49,'Curr Prices'!AE$11:AE$49,,0)*_xlfn.XLOOKUP($A7,'2024 Adj Factor'!$A$11:$A$49,'2024 Adj Factor'!$B$11:$B$49,,0),0) -> 105482.01
A8: Ireland | B8: =+IFERROR(_xlfn.XLOOKUP($A8,'Curr Prices'!$A$11:$A$49,'Curr Prices'!B$11:B$49,,0)*_xlfn.XLOOKUP($A8,'2024 Adj Factor'!$A$11:$A$49,'2024 Adj Factor'!$B$11:$B$49,,0),0) -> 110175.2 | C8: =+IFERROR(_xlfn.XLOOKUP($A8,'Curr Prices'!$A$11:$A$49,'Curr Prices'!C$11:C$49,,0)*_xlfn.XLOOKUP($A8,'2024 Adj Factor'!$A$11:$A$49,'2024 Adj Factor'!$B$11:$B$49,,0),0) -> 122121.4 | D8: =+IFERROR(_xlfn.XLOOKUP($A8,'Curr Prices'!$A$11:$A$49,'Curr Prices'!D$11:D$49,,0)*_xlfn.XLOOKUP($A8,'2024 Adj Factor'!$A$11:$A$49,'2024 Adj Factor'!$B$11:$B$49,,0),0) -> 150984.1 | E8: =+IFERROR(_xlfn.XLOOKUP($A8,'Curr Prices'!$A$11:$A$49,'Curr Prices'!E$11:E$49,,0)*_xlfn.XLOOKUP($A8,'2024 Adj Factor'!$A$11:$A$49,'2024 Adj Factor'!$B$11:$B$49,,0),0) -> 169828.1 | F8: =+IFERROR(_xlfn.XLOOKUP($A8,'Curr Prices'!$A$11:$A$49,'Curr Prices'!F$11:F$49,,0)*_xlfn.XLOOKUP($A8,'2024 Adj Factor'!$A$11:$A$49,'2024 Adj Factor'!$B$11:$B$49,,0),0) -> 191831.3 | G8: =+IFERROR(_xlfn.XLOOKUP($A8,'Curr Prices'!$A$11:$A$49,'Curr Prices'!G$11:G$49,,0)*_xlfn.XLOOKUP($A8,'2024 Adj Factor'!$A$11:$A$49,'2024 Adj Factor'!$B$11:$B$49,,0),0) -> 223420.3 | H8: =+IFERROR(_xlfn.XLOOKUP($A8,'Curr Prices'!$A$11:$A$49,'Curr Prices'!H$11:H$49,,0)*_xlfn.XLOOKUP($A8,'2024 Adj Factor'!$A$11:$A$49,'2024 Adj Factor'!$B$11:$B$49,,0),0) -> 253658.1 | I8: =+IFERROR(_xlfn.XLOOKUP($A8,'Curr Prices'!$A$11:$A$49,'Curr Prices'!I$11:I$49,,0)*_xlfn.XLOOKUP($A8,'2024 Adj Factor'!$A$11:$A$49,'2024 Adj Factor'!$B$11:$B$49,,0),0) -> 272849.8 | ... AE8: =+IFERROR(_xlfn.XLOOKUP($A8,'Curr Prices'!$A$11:$A$49,'Curr Prices'!AE$11:AE$49,,0)*_xlfn.XLOOKUP($A8,'2024 Adj Factor'!$A$11:$A$49,'2024 Adj Factor'!$B$11:$B$49,,0),0) -> 1127871.2
A9: Greece | B9: =+IFERROR(_xlfn.XLOOKUP($A9,'Curr Prices'!$A$11:$A$49,'Curr Prices'!B$11:B$49,,0)*_xlfn.XLOOKUP($A9,'2024 Adj Factor'!$A$11:$A$49,'2024 Adj Factor'!$B$11:$B$49,,0),0) -> 222088.47 | C9: =+IFERROR(_xlfn.XLOOKUP($A9,'Curr Prices'!$A$11:$A$49,'Curr Prices'!C$11:C$49,,0)*_xlfn.XLOOKUP($A9,'2024 Adj Factor'!$A$11:$A$49,'2024 Adj Factor'!$B$11:$B$49,,0),0) -> 239645.12 | D9: =+IFERROR(_xlfn.XLOOKUP($A9,'Curr Prices'!$A$11:$A$49,'Curr Prices'!D$11:D$49,,0)*_xlfn.XLOOKUP($A9,'2024 Adj Factor'!$A$11:$A$49,'2024 Adj Factor'!$B$11:$B$49,,0),0) -> 254625.6 | E9: =+IFERROR(_xlfn.XLOOKUP($A9,'Curr Prices'!$A$11:$A$49,'Curr Prices'!E$11:E$49,,0)*_xlfn.XLOOKUP($A9,'2024 Adj Factor'!$A$11:$A$49,'2024 Adj Factor'!$B$11:$B$49,,0),0) -> 258103.63 | F9: =+IFERROR(_xlfn.XLOOKUP($A9,'Curr Prices'!$A$11:$A$49,'Curr Prices'!F$11:F$49,,0)*_xlfn.XLOOKUP($A9,'2024 Adj Factor'!$A$11:$A$49,'2024 Adj Factor'!$B$11:$B$49,,0),0) -> 276945.4 | G9: =+IFERROR(_xlfn.XLOOKUP($A9,'Curr Prices'!$A$11:$A$49,'Curr Prices'!G$11:G$49,,0)*_xlfn.XLOOKUP($A9,'2024 Adj Factor'!$A$11:$A$49,'2024 Adj Factor'!$B$11:$B$49,,0),0) -> 289648.98 | H9: =+IFERROR(_xlfn.XLOOKUP($A9,'Curr Prices'!$A$11:$A$49,'Curr Prices'!H$11:H$49,,0)*_xlfn.XLOOKUP($A9,'2024 Adj Factor'!$A$11:$A$49,'2024 Adj Factor'!$B$11:$B$49,,0),0) -> 307010.72 | I9: =+IFERROR(_xlfn.XLOOKUP($A9,'Curr Prices'!$A$11:$A$49,'Curr Prices'!I$11:I$49,,0)*_xlfn.XLOOKUP($A9,'2024 Adj Factor'!$A$11:$A$49,'2024 Adj Factor'!$B$11:$B$49,,0),0) -> 329823.13 | ... AE9: =+IFERROR(_xlfn.XLOOKUP($A9,'Curr Prices'!$A$11:$A$49,'Curr Prices'!AE$11:AE$49,,0)*_xlfn.XLOOKUP($A9,'2024 Adj Factor'!$A$11:$A$49,'2024 Adj Factor'!$B$11:$B$49,,0),0) -> 501658.84
A10: Spain | B10: =+IFERROR(_xlfn.XLOOKUP($A10,'Curr Prices'!$A$11:$A$49,'Curr Prices'!B$11:B$49,,0)*_xlfn.XLOOKUP($A10,'2024 Adj Factor'!$A$11:$A$49,'2024 Adj Factor'!$B$11:$B$49,,0),0) -> 832054.4 | C10: =+IFERROR(_xlfn.XLOOKUP($A10,'Curr Prices'!$A$11:$A$49,'Curr Prices'!C$11:C$49,,0)*_xlfn.XLOOKUP($A10,'2024 Adj Factor'!$A$11:$A$49,'2024 Adj Factor'!$B$11:$B$49,,0),0) -> 900963.8 | D10: =+IFERROR(_xlfn.XLOOKUP($A10,'Curr Prices'!$A$11:$A$49,'Curr Prices'!D$11:D$49,,0)*_xlfn.XLOOKUP($A10,'2024 Adj Factor'!$A$11:$A$49,'2024 Adj Factor'!$B$11:$B$49,,0),0) -> 934207.6 | E10: =+IFERROR(_xlfn.XLOOKUP($A10,'Curr Prices'!$A$11:$A$49,'Curr Prices'!E$11:E$49,,0)*_xlfn.XLOOKUP($A10,'2024 Adj Factor'!$A$11:$A$49,'2024 Adj Factor'!$B$11:$B$49,,0),0) -> 995474.3 | F10: =+IFERROR(_xlfn.XLOOKUP($A10,'Curr Prices'!$A$11:$A$49,'Curr Prices'!F$11:F$49,,0)*_xlfn.XLOOKUP($A10,'2024 Adj Factor'!$A$11:$A$49,'2024 Adj Factor'!$B$11:$B$49,,0),0) -> 1085147 | G10: =+IFERROR(_xlfn.XLOOKUP($A10,'Curr Prices'!$A$11:$A$49,'Curr Prices'!G$11:G$49,,0)*_xlfn.XLOOKUP($A10,'2024 Adj Factor'!$A$11:$A$49,'2024 Adj Factor'!$B$11:$B$49,,0),0) -> 1210179 | H10: =+IFERROR(_xlfn.XLOOKUP($A10,'Curr Prices'!$A$11:$A$49,'Curr Prices'!H$11:H$49,,0)*_xlfn.XLOOKUP($A10,'2024 Adj Factor'!$A$11:$A$49,'2024 Adj Factor'!$B$11:$B$49,,0),0) -> 1315527 | I10: =+IFERROR(_xlfn.XLOOKUP($A10,'Curr Prices'!$A$11:$A$49,'Curr Prices'!I$11:I$49,,0)*_xlfn.XLOOKUP($A10,'2024 Adj Factor'!$A$11:$A$49,'2024 Adj Factor'!$B$11:$B$49,,0),0) -> 1428956 | ... AE10: =+IFERROR(_xlfn.XLOOKUP($A10,'Curr Prices'!$A$11:$A$49,'Curr Prices'!AE$11:AE$49,,0)*_xlfn.XLOOKUP($A10,'2024 Adj Factor'!$A$11:$A$49,'2024 Adj Factor'!$B$11:$B$49,,0),0) -> 2946682
A11: France | B11: =+IFERROR(_xlfn.XLOOKUP($A11,'Curr Prices'!$A$11:$A$49,'Curr Prices'!B$11:B$49,,0)*_xlfn.XLOOKUP($A11,'2024 Adj Factor'!$A$11:$A$49,'2024 Adj Factor'!$B$11:$B$49,,0),0) -> 2363637.7 | C11: =+IFERROR(_xlfn.XLOOKUP($A11,'Curr Prices'!$A$11:$A$49,'Curr Prices'!C$11:C$49,,0)*_xlfn.XLOOKUP($A11,'2024 Adj Factor'!$A$11:$A$49,'2024 Adj Factor'!$B$11:$B$49,,0),0) -> 2426670.6 | D11: =+IFERROR(_xlfn.XLOOKUP($A11,'Curr Prices'!$A$11:$A$49,'Curr Prices'!D$11:D$49,,0)*_xlfn.XLOOKUP($A11,'2024 Adj Factor'!$A$11:$A$49,'2024 Adj Factor'!$B$11:$B$49,,0),0) -> 2478840.9 | E11: =+IFERROR(_xlfn.XLOOKUP($A11,'Curr Prices'!$A$11:$A$49,'Curr Prices'!E$11:E$49,,0)*_xlfn.XLOOKUP($A11,'2024 Adj Factor'!$A$11:$A$49,'2024 Adj Factor'!$B$11:$B$49,,0),0) -> 2594049.9 | F11: =+IFERROR(_xlfn.XLOOKUP($A11,'Curr Prices'!$A$11:$A$49,'Curr Prices'!F$11:F$49,,0)*_xlfn.XLOOKUP($A11,'2024 Adj Factor'!$A$11:$A$49,'2024 Adj Factor'!$B$11:$B$49,,0),0) -> 2743465.2 | G11: =+IFERROR(_xlfn.XLOOKUP($A11,'Curr Prices'!$A$11:$A$49,'Curr Prices'!G$11:G$49,,0)*_xlfn.XLOOKUP($A11,'2024 Adj Factor'!$A$11:$A$49,'2024 Adj Factor'!$B$11:$B$49,,0),0) -> 2980562.2 | H11: =+IFERROR(_xlfn.XLOOKUP($A11,'Curr Prices'!$A$11:$A$49,'Curr Prices'!H$11:H$49,,0)*_xlfn.XLOOKUP($A11,'2024 Adj Factor'!$A$11:$A$49,'2024 Adj Factor'!$B$11:$B$49,,0),0) -> 3117764.7 | I11: =+IFERROR(_xlfn.XLOOKUP($A11,'Curr Prices'!$A$11:$A$49,'Curr Prices'!I$11:I$49,,0)*_xlfn.XLOOKUP($A11,'2024 Adj Factor'!$A$11:$A$49,'2024 Adj Factor'!$B$11:$B$49,,0),0) -> 3185134.4 | ... AE11: =+IFERROR(_xlfn.XLOOKUP($A11,'Curr Prices'!$A$11:$A$49,'Curr Prices'!AE$11:AE$49,,0)*_xlfn.XLOOKUP($A11,'2024 Adj Factor'!$A$11:$A$49,'2024 Adj Factor'!$B$11:$B$49,,0),0) -> 6122080.8
A12: Croatia | B12: =+IFERROR(_xlfn.XLOOKUP($A12,'Curr Prices'!$A$11:$A$49,'Curr Prices'!B$11:B$49,,0)*_xlfn.XLOOKUP($A12,'2024 Adj Factor'!$A$11:$A$49,'2024 Adj Factor'!$B$11:$B$49,,0),0) -> 32396.8 | C12: =+IFERROR(_xlfn.XLOOKUP($A12,'Curr Prices'!$A$11:$A$49,'Curr Prices'!C$11:C$49,,0)*_xlfn.XLOOKUP($A12,'2024 Adj Factor'!$A$11:$A$49,'2024 Adj Factor'!$B$11:$B$49,,0),0) -> 35281 | D12: =+IFERROR(_xlfn.XLOOKUP($A12,'Curr Prices'!$A$11:$A$49,'Curr Prices'!D$11:D$49,,0)*_xlfn.XLOOKUP($A12,'2024 Adj Factor'!$A$11:$A$49,'2024 Adj Factor'!$B$11:$B$49,,0),0) -> 39704.8 | E12: =+IFERROR(_xlfn.XLOOKUP($A12,'Curr Prices'!$A$11:$A$49,'Curr Prices'!E$11:E$49,,0)*_xlfn.XLOOKUP($A12,'2024 Adj Factor'!$A$11:$A$49,'2024 Adj Factor'!$B$11:$B$49,,0),0) -> 39475 | F12: =+IFERROR(_xlfn.XLOOKUP($A12,'Curr Prices'!$A$11:$A$49,'Curr Prices'!F$11:F$49,,0)*_xlfn.XLOOKUP($A12,'2024 Adj Factor'!$A$11:$A$49,'2024 Adj Factor'!$B$11:$B$49,,0),0) -> 37954.8 | G12: =+IFERROR(_xlfn.XLOOKUP($A12,'Curr Prices'!$A$11:$A$49,'Curr Prices'!G$11:G$49,,0)*_xlfn.XLOOKUP($A12,'2024 Adj Factor'!$A$11:$A$49,'2024 Adj Factor'!$B$11:$B$49,,0),0) -> 40104.1 | H12: =+IFERROR(_xlfn.XLOOKUP($A12,'Curr Prices'!$A$11:$A$49,'Curr Prices'!H$11:H$49,,0)*_xlfn.XLOOKUP($A12,'2024 Adj Factor'!$A$11:$A$49,'2024 Adj Factor'!$B$11:$B$49,,0),0) -> 44063.7 | I12: =+IFERROR(_xlfn.XLOOKUP($A12,'Curr Prices'!$A$11:$A$49,'Curr Prices'!I$11:I$49,,0)*_xlfn.XLOOKUP($A12,'2024 Adj Factor'!$A$11:$A$49,'2024 Adj Factor'!$B$11:$B$49,,0),0) -> 49086.3 | ... AE12: =+IFERROR(_xlfn.XLOOKUP($A12,'Curr Prices'!$A$11:$A$49,'Curr Prices'!AE$11:AE$49,,0)*_xlfn.XLOOKUP($A12,'2024 Adj Factor'!$A$11:$A$49,'2024 Adj Factor'!$B$11:$B$49,,0),0) -> 144486.1
